Workbook

Sheet ml_challenge_dataset
A1: unique_id | B1: Painting | C1: On a scale of 1‚Äì10, how intense is the emotion conveyed by the artwork? | D1: Describe how this painting makes you feel. | E1: This art piece makes me feel sombre. | F1: This art piece makes me feel content. | G1: This art piece makes me feel calm. | H1: This art piece makes me feel uneasy. | I1: How many prominent colours do you notice in this painting? | J1: How many objects caught your eye in the painting? | K1: How much (in Canadian dollars) would you be willing to pay for this painting? | L1: If you could purchase this painting, which room would you put that painting in? | M1: If you could view this art in person, who would you want to view it with? | N1: What season does this art piece remind you of? | O1: If this painting was a food, what would be? | P1: Imagine a soundtrack for this painting. Describe that soundtrack without naming any objects in the painting. | Q1: Sombre Score | R1: Content Score | S1: Calm Score | T1: Uneasy Score | U1: Willingness to Pay (CAD) | V1: Bathroom | W1: Dining room | X1: Office | Y1: Bedroom | Z1: Living room | AA1: By Yourself | AB1: Friends | AC1: Family members | AD1: Coworkers/Classmates | AE1: Strangers | AF1: Spring | AG1: Summer | AH1: Fall | AI1: Winter
A2: 1 | B2: The Persistence of Memory | I2: 5 | Q2: =IF(E2="", "", LEFT(E2, 1) * 1) | R2: =IF(F2="","",VALUE(LEFT(F2,FIND(" ",F2)-1))) | S2: =IF(G2="","",VALUE(LEFT(G2,FIND(" ",G2)-1))) | T2: =IF(H2="","",VALUE(LEFT(H2,FIND(" ",H2)-1))) | V2: =IF(L2="",0,IF(ISNUMBER(SEARCH("Bathroom",L2)),1,0)) -> 0 | W2: =IF(L2="",0,IF(ISNUMBER(SEARCH("Dining room",L2)),1,0)) -> 0 | X2: =IF(L2="",0,IF(ISNUMBER(SEARCH("Office",L2)),1,0)) -> 0 | Y2: =IF(L2="",0,IF(ISNUMBER(SEARCH("Bedroom",L2)),1,0)) -> 0 | Z2: =IF(L2="",0,IF(ISNUMBER(SEARCH("Living room",L2)),1,0)) -> 0 | AA2: =IF(M2="",0, IF(ISNUMBER(SEARCH("By yourself",M2)), 1, 0)) -> 0 | AB2: =IF(M2="", 0, IF(ISNUMBER(SEARCH("Friends", M2)), 1, 0)) -> 0 | AC2: =IF(M2="",0,IF(ISNUMBER(SEARCH("Family members", M2)), 1, 0)) -> 0 | AD2: =IF(M2="", 0, IF(ISNUMBER(SEARCH("Coworkers/Classmates", M2)), 1, 0)) -> 0 | AE2: =IF(M2="", 0, IF(ISNUMBER(SEARCH("Strangers", M2)), 1, 0)) -> 0 | AF2: =IF(N2="", 0, IF(ISNUMBER(SEARCH("Spring", N2)), 1, 0)) -> 0 | AG2: =IF(N2="", 0, IF(ISNUMBER(SEARCH("Summer", N2)), 1, 0)) -> 0 | AH2: =IF(N2="", 0, IF(ISNUMBER(SEARCH("Fall", N2)), 1, 0)) -> 0 | AI2: =IF(N2="", 0, IF(ISNUMBER(SEARCH("Winter", N2)), 1, 0)) -> 0
A3: 2 | B3: The Persistence of Memory | C3: 5 | D3: The clocks are burnt on a hot desert, it embodies the melancholy of time passing. The dominant yellow hue intensifies this sensation. | E3: 4 - Agree | F3: 3 - Neutral/Unsure | G3: 2 - Disagree | H3: 1 - Strongly disagree | I3: 2 | J3: 4 | K3: 0 | L3: Bathroom | M3: By yourself | N3: Fall | O3: Fries | P3: A country song that contrasts nostalgia for the past with dissatisfaction with the present. | Q3: =IF(E3="", "", LEFT(E3, 1) * 1) -> 4 | R3: =IF(F3="","",VALUE(LEFT(F3,FIND(" ",F3)-1))) -> 3 | S3: =IF(G3="","",VALUE(LEFT(G3,FIND(" ",G3)-1))) -> 2 | T3: =IF(H3="","",VALUE(LEFT(H3,FIND(" ",H3)-1))) -> 1 | U3: 0 | V3: =IF(L3="",0,IF(ISNUMBER(SEARCH("Bathroom",L3)),1,0)) -> 1 | W3: =IF(L3="",0,IF(ISNUMBER(SEARCH("Dining room",L3)),1,0)) -> 0 | X3: =IF(L3="",0,IF(ISNUMBER(SEARCH("Office",L3)),1,0)) -> 0 | Y3: =IF(L3="",0,IF(ISNUMBER(SEARCH("Bedroom",L3)),1,0)) -> 0 | Z3: =IF(L3="",0,IF(ISNUMBER(SEARCH("Living room",L3)),1,0)) -> 0 | AA3: =IF(M3="",0, IF(ISNUMBER(SEARCH("By yourself",M3)), 1, 0)) -> 1 | AB3: =IF(M3="", 0, IF(ISNUMBER(SEARCH("Friends", M3)), 1, 0)) -> 0 | AC3: =IF(M3="",0,IF(ISNUMBER(SEARCH("Family members", M3)), 1, 0)) -> 0 | AD3: =IF(M3="", 0, IF(ISNUMBER(SEARCH("Coworkers/Classmates", M3)), 1, 0)) -> 0 | AE3: =IF(M3="", 0, IF(ISNUMBER(SEARCH("Strangers", M3)), 1, 0)) -> 0 | AF3: =IF(N3="", 0, IF(ISNUMBER(SEARCH("Spring", N3)), 1, 0)) -> 0 | AG3: =IF(N3="", 0, IF(ISNUMBER(SEARCH("Summer", N3)), 1, 0)) -> 0 | AH3: =IF(N3="", 0, IF(ISNUMBER(SEARCH("Fall", N3)), 1, 0)) -> 1 | AI3: =IF(N3="", 0, IF(ISNUMBER(SEARCH("Winter", N3)), 1, 0)) -> 0
A4: 3 | B4: The Persistence of Memory | C4: 7 | D4: This painting makes me feel dread. The clock reminds me of a ticking time until the death of the creature in the picture. | E4: 4 - Agree | F4: 1 - Strongly disagree | G4: 1 - Strongly disagree | H4: 4 - Agree | I4: 4 | J4: 3 | K4: 5 | L4: Bathroom,Dining room | M4: Coworkers/Classmates,By yourself | N4: Fall | O4: Sardines | P4: A melancholy instrumental with a monotone voice singing gloomy lyrics like Creep by radiohead. | Q4: =IF(E4="", "", LEFT(E4, 1) * 1) -> 4 | R4: =IF(F4="","",VALUE(LEFT(F4,FIND(" ",F4)-1))) -> 1 | S4: =IF(G4="","",VALUE(LEFT(G4,FIND(" ",G4)-1))) -> 1 | T4: =IF(H4="","",VALUE(LEFT(H4,FIND(" ",H4)-1))) -> 4 | U4: 5 | V4: =IF(L4="",0,IF(ISNUMBER(SEARCH("Bathroom",L4)),1,0)) -> 1 | W4: =IF(L4="",0,IF(ISNUMBER(SEARCH("Dining room",L4)),1,0)) -> 1 | X4: =IF(L4="",0,IF(ISNUMBER(SEARCH("Office",L4)),1,0)) -> 0 | Y4: =IF(L4="",0,IF(ISNUMBER(SEARCH("Bedroom",L4)),1,0)) -> 0 | Z4: =IF(L4="",0,IF(ISNUMBER(SEARCH("Living room",L4)),1,0)) -> 0 | AA4: =IF(M4="",0, IF(ISNUMBER(SEARCH("By yourself",M4)), 1, 0)) -> 1 | AB4: =IF(M4="", 0, IF(ISNUMBER(SEARCH("Friends", M4)), 1, 0)) -> 0 | AC4: =IF(M4="",0,IF(ISNUMBER(SEARCH("Family members", M4)), 1, 0)) -> 0 | AD4: =IF(M4="", 0, IF(ISNUMBER(SEARCH("Coworkers/Classmates", M4)), 1, 0)) -> 1 | AE4: =IF(M4="", 0, IF(ISNUMBER(SEARCH("Strangers", M4)), 1, 0)) -> 0 | AF4: =IF(N4="", 0, IF(ISNUMBER(SEARCH("Spring", N4)), 1, 0)) -> 0 | AG4: =IF(N4="", 0, IF(ISNUMBER(SEARCH("Summer", N4)), 1, 0)) -> 0 | AH4: =IF(N4="", 0, IF(ISNUMBER(SEARCH("Fall", N4)), 1, 0)) -> 1 | AI4: =IF(N4="", 0, IF(ISNUMBER(SEARCH("Winter", N4)), 1, 0)) -> 0
A5: 4 | B5: The Persistence of Memory | C5: 7 | D5: Deflated | E5: 4 - Agree | F5: 1 - Strongly disagree | G5: 2 - Disagree | H5: 4 - Agree | I5: 10 | J5: 7 | K5: a | L5: Bedroom,Bathroom | M5: Coworkers/Classmates | N5: Winter | O5: a | P5: q | Q5: =IF(E5="", "", LEFT(E5, 1) * 1) -> 4 | R5: =IF(F5="","",VALUE(LEFT(F5,FIND(" ",F5)-1))) -> 1 | S5: =IF(G5="","",VALUE(LEFT(G5,FIND(" ",G5)-1))) -> 2 | T5: =IF(H5="","",VALUE(LEFT(H5,FIND(" ",H5)-1))) -> 4 | V5: =IF(L5="",0,IF(ISNUMBER(SEARCH("Bathroom",L5)),1,0)) -> 1 | W5: =IF(L5="",0,IF(ISNUMBER(SEARCH("Dining room",L5)),1,0)) -> 0 | X5: =IF(L5="",0,IF(ISNUMBER(SEARCH("Office",L5)),1,0)) -> 0 | Y5: =IF(L5="",0,IF(ISNUMBER(SEARCH("Bedroom",L5)),1,0)) -> 1 | Z5: =IF(L5="",0,IF(ISNUMBER(SEARCH("Living room",L5)),1,0)) -> 0 | AA5: =IF(M5="",0, IF(ISNUMBER(SEARCH("By yourself",M5)), 1, 0)) -> 0 | AB5: =IF(M5="", 0, IF(ISNUMBER(SEARCH("Friends", M5)), 1, 0)) -> 0 | AC5: =IF(M5="",0,IF(ISNUMBER(SEARCH("Family members", M5)), 1, 0)) -> 0 | AD5: =IF(M5="", 0, IF(ISNUMBER(SEARCH("Coworkers/Classmates", M5)), 1, 0)) -> 1 | AE5: =IF(M5="", 0, IF(ISNUMBER(SEARCH("Strangers", M5)), 1, 0)) -> 0 | AF5: =IF(N5="", 0, IF(ISNUMBER(SEARCH("Spring", N5)), 1, 0)) -> 0 | AG5: =IF(N5="", 0, IF(ISNUMBER(SEARCH("Summer", N5)), 1, 0)) -> 0 | AH5: =IF(N5="", 0, IF(ISNUMBER(SEARCH("Fall", N5)), 1, 0)) -> 0 | AI5: =IF(N5="", 0, IF(ISNUMBER(SEARCH("Winter", N5)), 1, 0)) -> 1
A6: 5 | B6: The Persistence of Memory | C6: 7 | D6: The painting gives me a sense of calmness and plenitude. It has an ominous and nostalgic feeling similar to time passing.¬† | E6: 3 - Neutral/Unsure | F6: 4 - Agree | G6: 5 - Strongly agree | H6: 3 - Neutral/Unsure | I6: 4 | J6: 6 | K6: 300 dollars. | L6: Living room | M6: Friends | N6: Spring,Summer | O6: Churros. | P6: Radiohead's album in rainbows. | Q6: =IF(E6="", "", LEFT(E6, 1) * 1) -> 3 | R6: =IF(F6="","",VALUE(LEFT(F6,FIND(" ",F6)-1))) -> 4 | S6: =IF(G6="","",VALUE(LEFT(G6,FIND(" ",G6)-1))) -> 5 | T6: =IF(H6="","",VALUE(LEFT(H6,FIND(" ",H6)-1))) -> 3 | U6: 300 | V6: =IF(L6="",0,IF(ISNUMBER(SEARCH("Bathroom",L6)),1,0)) -> 0 | W6: =IF(L6="",0,IF(ISNUMBER(SEARCH("Dining room",L6)),1,0)) -> 0 | X6: =IF(L6="",0,IF(ISNUMBER(SEARCH("Office",L6)),1,0)) -> 0 | Y6: =IF(L6="",0,IF(ISNUMBER(SEARCH("Bedroom",L6)),1,0)) -> 0 | Z6: =IF(L6="",0,IF(ISNUMBER(SEARCH("Living room",L6)),1,0)) -> 1 | AA6: =IF(M6="",0, IF(ISNUMBER(SEARCH("By yourself",M6)), 1, 0)) -> 0 | AB6: =IF(M6="", 0, IF(ISNUMBER(SEARCH("Friends", M6)), 1, 0)) -> 1 | AC6: =IF(M6="",0,IF(ISNUMBER(SEARCH("Family members", M6)), 1, 0)) -> 0 | AD6: =IF(M6="", 0, IF(ISNUMBER(SEARCH("Coworkers/Classmates", M6)), 1, 0)) -> 0 | AE6: =IF(M6="", 0, IF(ISNUMBER(SEARCH("Strangers", M6)), 1, 0)) -> 0 | AF6: =IF(N6="", 0, IF(ISNUMBER(SEARCH("Spring", N6)), 1, 0)) -> 1 | AG6: =IF(N6="", 0, IF(ISNUMBER(SEARCH("Summer", N6)), 1, 0)) -> 1 | AH6: =IF(N6="", 0, IF(ISNUMBER(SEARCH("Fall", N6)), 1, 0)) -> 0 | AI6: =IF(N6="", 0, IF(ISNUMBER(SEARCH("Winter", N6)), 1, 0)) -> 0
A7: 6 | B7: The Persistence of Memory | C7: 7 | D7: This painting makes me feel a bit confused and bewildered, as the objects and art style make me feel detached from reality. | E7: 4 - Agree | F7: 2 - Disagree | G7: 1 - Strongly disagree | H7: 5 - Strongly agree | I7: 5 | J7: 6 | K7: 90000 | L7: Office,Living room | M7: Friends,Family members,By yourself | N7: Summer,Fall | O7: Shepherd's pie | P7: The soundtrack should sound heavy, sombre, and like a finale to an event. It should be slow but without too much emotion. | Q7: =IF(E7="", "", LEFT(E7, 1) * 1) -> 4 | R7: =IF(F7="","",VALUE(LEFT(F7,FIND(" ",F7)-1))) -> 2 | S7: =IF(G7="","",VALUE(LEFT(G7,FIND(" ",G7)-1))) -> 1 | T7: =IF(H7="","",VALUE(LEFT(H7,FIND(" ",H7)-1))) -> 5 | U7: 90000 | V7: =IF(L7="",0,IF(ISNUMBER(SEARCH("Bathroom",L7)),1,0)) -> 0 | W7: =IF(L7="",0,IF(ISNUMBER(SEARCH("Dining room",L7)),1,0)) -> 0 | X7: =IF(L7="",0,IF(ISNUMBER(SEARCH("Office",L7)),1,0)) -> 1 | Y7: =IF(L7="",0,IF(ISNUMBER(SEARCH("Bedroom",L7)),1,0)) -> 0 | Z7: =IF(L7="",0,IF(ISNUMBER(SEARCH("Living room",L7)),1,0)) -> 1 | AA7: =IF(M7="",0, IF(ISNUMBER(SEARCH("By yourself",M7)), 1, 0)) -> 1 | AB7: =IF(M7="", 0, IF(ISNUMBER(SEARCH("Friends", M7)), 1, 0)) -> 1 | AC7: =IF(M7="",0,IF(ISNUMBER(SEARCH("Family members", M7)), 1, 0)) -> 1 | AD7: =IF(M7="", 0, IF(ISNUMBER(SEARCH("Coworkers/Classmates", M7)), 1, 0)) -> 0 | AE7: =IF(M7="", 0, IF(ISNUMBER(SEARCH("Strangers", M7)), 1, 0)) -> 0 | AF7: =IF(N7="", 0, IF(ISNUMBER(SEARCH("Spring", N7)), 1, 0)) -> 0 | AG7: =IF(N7="", 0, IF(ISNUMBER(SEARCH("Summer", N7)), 1, 0)) -> 1 | AH7: =IF(N7="", 0, IF(ISNUMBER(SEARCH("Fall", N7)), 1, 0)) -> 1 | AI7: =IF(N7="", 0, IF(ISNUMBER(SEARCH("Winter", N7)), 1, 0)) -> 0
A8: 7 | B8: The Persistence of Memory | C8: 8 | D8: It has a sorrow feeling and clock is melting feel like time is decaying. | E8: 4 - Agree | F8: 2 - Disagree | G8: 2 - Disagree | H8: 4 - Agree | I8: 3 | J8: 3 | K8: 0 | L8: Office | M8: By yourself | N8: Winter | O8: 10 days old lasagna | P8: A truly sorrow, minor key orchestra piece | Q8: =IF(E8="", "", LEFT(E8, 1) * 1) -> 4 | R8: =IF(F8="","",VALUE(LEFT(F8,FIND(" ",F8)-1))) -> 2 | S8: =IF(G8="","",VALUE(LEFT(G8,FIND(" ",G8)-1))) -> 2 | T8: =IF(H8="","",VALUE(LEFT(H8,FIND(" ",H8)-1))) -> 4 | U8: 0 | V8: =IF(L8="",0,IF(ISNUMBER(SEARCH("Bathroom",L8)),1,0)) -> 0 | W8: =IF(L8="",0,IF(ISNUMBER(SEARCH("Dining room",L8)),1,0)) -> 0 | X8: =IF(L8="",0,IF(ISNUMBER(SEARCH("Office",L8)),1,0)) -> 1 | Y8: =IF(L8="",0,IF(ISNUMBER(SEARCH("Bedroom",L8)),1,0)) -> 0 | Z8: =IF(L8="",0,IF(ISNUMBER(SEARCH("Living room",L8)),1,0)) -> 0 | AA8: =IF(M8="",0, IF(ISNUMBER(SEARCH("By yourself",M8)), 1, 0)) -> 1 | AB8: =IF(M8="", 0, IF(ISNUMBER(SEARCH("Friends", M8)), 1, 0)) -> 0 | AC8: =IF(M8="",0,IF(ISNUMBER(SEARCH("Family members", M8)), 1, 0)) -> 0 | AD8: =IF(M8="", 0, IF(ISNUMBER(SEARCH("Coworkers/Classmates", M8)), 1, 0)) -> 0 | AE8: =IF(M8="", 0, IF(ISNUMBER(SEARCH("Strangers", M8)), 1, 0)) -> 0 | AF8: =IF(N8="", 0, IF(ISNUMBER(SEARCH("Spring", N8)), 1, 0)) -> 0 | AG8: =IF(N8="", 0, IF(ISNUMBER(SEARCH("Summer", N8)), 1, 0)) -> 0 | AH8: =IF(N8="", 0, IF(ISNUMBER(SEARCH("Fall", N8)), 1, 0)) -> 0 | AI8: =IF(N8="", 0, IF(ISNUMBER(SEARCH("Winter", N8)), 1, 0)) -> 1
A9: 8 | B9: The Persistence of Memory | C9: 4 | D9: The painting makes me feel somewhat sad, thinking about the passage of time. | E9: 4 - Agree | F9: 2 - Disagree | G9: 2 - Disagree | H9: 4 - Agree | I9: 7 | J9: 8 | K9: 150 | L9: Office | M9: By yourself | N9: Winter | O9: Grilled Salmon with a Beurre Blanc sauce. | P9: Slow, somewhat sad piano or violin piece. | Q9: =IF(E9="", "", LEFT(E9, 1) * 1) -> 4 | R9: =IF(F9="","",VALUE(LEFT(F9,FIND(" ",F9)-1))) -> 2 | S9: =IF(G9="","",VALUE(LEFT(G9,FIND(" ",G9)-1))) -> 2 | T9: =IF(H9="","",VALUE(LEFT(H9,FIND(" ",H9)-1))) -> 4 | U9: 150 | V9: =IF(L9="",0,IF(ISNUMBER(SEARCH("Bathroom",L9)),1,0)) -> 0 | W9: =IF(L9="",0,IF(ISNUMBER(SEARCH("Dining room",L9)),1,0)) -> 0 | X9: =IF(L9="",0,IF(ISNUMBER(SEARCH("Office",L9)),1,0)) -> 1 | Y9: =IF(L9="",0,IF(ISNUMBER(SEARCH("Bedroom",L9)),1,0)) -> 0 | Z9: =IF(L9="",0,IF(ISNUMBER(SEARCH("Living room",L9)),1,0)) -> 0 | AA9: =IF(M9="",0, IF(ISNUMBER(SEARCH("By yourself",M9)), 1, 0)) -> 1 | AB9: =IF(M9="", 0, IF(ISNUMBER(SEARCH("Friends", M9)), 1, 0)) -> 0 | AC9: =IF(M9="",0,IF(ISNUMBER(SEARCH("Family members", M9)), 1, 0)) -> 0 | AD9: =IF(M9="", 0, IF(ISNUMBER(SEARCH("Coworkers/Classmates", M9)), 1, 0)) -> 0 | AE9: =IF(M9="", 0, IF(ISNUMBER(SEARCH("Strangers", M9)), 1, 0)) -> 0 | AF9: =IF(N9="", 0, IF(ISNUMBER(SEARCH("Spring", N9)), 1, 0)) -> 0 | AG9: =IF(N9="", 0, IF(ISNUMBER(SEARCH("Summer", N9)), 1, 0)) -> 0 | AH9: =IF(N9="", 0, IF(ISNUMBER(SEARCH("Fall", N9)), 1, 0)) -> 0 | AI9: =IF(N9="", 0, IF(ISNUMBER(SEARCH("Winter", N9)), 1, 0)) -> 1
A10: 9 | B10: The Persistence of Memory | C10: 8 | D10: eerie, moody, confused | E10: 5 - Strongly agree | F10: 2 - Disagree | G10: 2 - Disagree | H10: 4 - Agree | I10: 3 | J10: 4 | K10: 20 | L10: Office | M10: Friends | N10: Fall | O10: pizza | P10: ticking clock horror movie soundtrack | Q10: =IF(E10="", "", LEFT(E10, 1) * 1) -> 5 | R10: =IF(F10="","",VALUE(LEFT(F10,FIND(" ",F10)-1))) -> 2 | S10: =IF(G10="","",VALUE(LEFT(G10,FIND(" ",G10)-1))) -> 2 | T10: =IF(H10="","",VALUE(LEFT(H10,FIND(" ",H10)-1))) -> 4 | U10: 20 | V10: =IF(L10="",0,IF(ISNUMBER(SEARCH("Bathroom",L10)),1,0)) -> 0 | W10: =IF(L10="",0,IF(ISNUMBER(SEARCH("Dining room",L10)),1,0)) -> 0 | X10: =IF(L10="",0,IF(ISNUMBER(SEARCH("Office",L10)),1,0)) -> 1 | Y10: =IF(L10="",0,IF(ISNUMBER(SEARCH("Bedroom",L10)),1,0)) -> 0 | Z10: =IF(L10="",0,IF(ISNUMBER(SEARCH("Living room",L10)),1,0)) -> 0 | AA10: =IF(M10="",0, IF(ISNUMBER(SEARCH("By yourself",M10)), 1, 0)) -> 0 | AB10: =IF(M10="", 0, IF(ISNUMBER(SEARCH("Friends", M10)), 1, 0)) -> 1 | AC10: =IF(M10="",0,IF(ISNUMBER(SEARCH("Family members", M10)), 1, 0)) -> 0 | AD10: =IF(M10="", 0, IF(ISNUMBER(SEARCH("Coworkers/Classmates", M10)), 1, 0)) -> 0 | AE10: =IF(M10="", 0, IF(ISNUMBER(SEARCH("Strangers", M10)), 1, 0)) -> 0 | AF10: =IF(N10="", 0, IF(ISNUMBER(SEARCH("Spring", N10)), 1, 0)) -> 0 | AG10: =IF(N10="", 0, IF(ISNUMBER(SEARCH("Summer", N10)), 1, 0)) -> 0 | AH10: =IF(N10="", 0, IF(ISNUMBER(SEARCH("Fall", N10)), 1, 0)) -> 1 | AI10: =IF(N10="", 0, IF(ISNUMBER(SEARCH("Winter", N10)), 1, 0)) -> 0
A11: 10 | B11: The Persistence of Memory | C11: 10 | D11: The painting gives me a sense of nostalgia and mourning. Although the setting is surreal, it feels like I am looking at a part of my life which has gone and passed forever and is warped upon reflection. | E11: 5 - Strongly agree | F11: 3 - Neutral/Unsure | G11: 1 - Strongly disagree | H11: 5 - Strongly agree | I11: 3 | J11: 5 | K11: 100000000 | L11: Living room | M11: Friends,Family members,By yourself | N11: Fall | O11: flan | P11: The soundtrack would be somber and nostalgic, with a solemn yearning for the past.¬† | Q11: =IF(E11="", "", LEFT(E11, 1) * 1) -> 5 | R11: =IF(F11="","",VALUE(LEFT(F11,FIND(" ",F11)-1))) -> 3 | S11: =IF(G11="","",VALUE(LEFT(G11,FIND(" ",G11)-1))) -> 1 | T11: =IF(H11="","",VALUE(LEFT(H11,FIND(" ",H11)-1))) -> 5 | U11: 100000000 | V11: =IF(L11="",0,IF(ISNUMBER(SEARCH("Bathroom",L11)),1,0)) -> 0 | W11: =IF(L11="",0,IF(ISNUMBER(SEARCH("Dining room",L11)),1,0)) -> 0 | X11: =IF(L11="",0,IF(ISNUMBER(SEARCH("Office",L11)),1,0)) -> 0 | Y11: =IF(L11="",0,IF(ISNUMBER(SEARCH("Bedroom",L11)),1,0)) -> 0 | Z11: =IF(L11="",0,IF(ISNUMBER(SEARCH("Living room",L11)),1,0)) -> 1 | AA11: =IF(M11="",0, IF(ISNUMBER(SEARCH("By yourself",M11)), 1, 0)) -> 1 | AB11: =IF(M11="", 0, IF(ISNUMBER(SEARCH("Friends", M11)), 1, 0)) -> 1 | AC11: =IF(M11="",0,IF(ISNUMBER(SEARCH("Family members", M11)), 1, 0)) -> 1 | AD11: =IF(M11="", 0, IF(ISNUMBER(SEARCH("Coworkers/Classmates", M11)), 1, 0)) -> 0 | AE11: =IF(M11="", 0, IF(ISNUMBER(SEARCH("Strangers", M11)), 1, 0)) -> 0 | AF11: =IF(N11="", 0, IF(ISNUMBER(SEARCH("Spring", N11)), 1, 0)) -> 0 | AG11: =IF(N11="", 0, IF(ISNUMBER(SEARCH("Summer", N11)), 1, 0)) -> 0 | AH11: =IF(N11="", 0, IF(ISNUMBER(SEARCH("Fall", N11)), 1, 0)) -> 1 | AI11: =IF(N11="", 0, IF(ISNUMBER(SEARCH("Winter", N11)), 1, 0)) -> 0
A12: 11 | B12: The Persistence of Memory | C12: 7 | D12: The painting makes me feel lathargic. | E12: 4 - Agree | F12: 2 - Disagree | G12: 4 - Agree | H12: 3 - Neutral/Unsure | I12: 3 | J12: 5 | K12: 400 | L12: Office,Dining room | M12: By yourself | N12: Fall | O12: Soup | P12: Low bpm | Q12: =IF(E12="", "", LEFT(E12, 1) * 1) -> 4 | R12: =IF(F12="","",VALUE(LEFT(F12,FIND(" ",F12)-1))) -> 2 | S12: =IF(G12="","",VALUE(LEFT(G12,FIND(" ",G12)-1))) -> 4 | T12: =IF(H12="","",VALUE(LEFT(H12,FIND(" ",H12)-1))) -> 3 | U12: 400 | V12: =IF(L12="",0,IF(ISNUMBER(SEARCH("Bathroom",L12)),1,0)) -> 0 | W12: =IF(L12="",0,IF(ISNUMBER(SEARCH("Dining room",L12)),1,0)) -> 1 | X12: =IF(L12="",0,IF(ISNUMBER(SEARCH("Office",L12)),1,0)) -> 1 | Y12: =IF(L12="",0,IF(ISNUMBER(SEARCH("Bedroom",L12)),1,0)) -> 0 | Z12: =IF(L12="",0,IF(ISNUMBER(SEARCH("Living room",L12)),1,0)) -> 0 | AA12: =IF(M12="",0, IF(ISNUMBER(SEARCH("By yourself",M12)), 1, 0)) -> 1 | AB12: =IF(M12="", 0, IF(ISNUMBER(SEARCH("Friends", M12)), 1, 0)) -> 0 | AC12: =IF(M12="",0,IF(ISNUMBER(SEARCH("Family members", M12)), 1, 0)) -> 0 | AD12: =IF(M12="", 0, IF(ISNUMBER(SEARCH("Coworkers/Classmates", M12)), 1, 0)) -> 0 | AE12: =IF(M12="", 0, IF(ISNUMBER(SEARCH("Strangers", M12)), 1, 0)) -> 0 | AF12: =IF(N12="", 0, IF(ISNUMBER(SEARCH("Spring", N12)), 1, 0)) -> 0 | AG12: =IF(N12="", 0, IF(ISNUMBER(SEARCH("Summer", N12)), 1, 0)) -> 0 | AH12: =IF(N12="", 0, IF(ISNUMBER(SEARCH("Fall", N12)), 1, 0)) -> 1 | AI12: =IF(N12="", 0, IF(ISNUMBER(SEARCH("Winter", N12)), 1, 0)) -> 0
A13: 12 | B13: The Persistence of Memory | C13: 8 | D13: World goes to an end. | E13: 3 - Neutral/Unsure | F13: 2 - Disagree | G13: 3 - Neutral/Unsure | H13: 3 - Neutral/Unsure | I13: 3 | J13: 3 | K13: 1000 | L13: Bedroom | M13: Friends,Family members,By yourself | N13: Fall | O13: A black chocolate. | P13: The soundtrack is cold, giving a scene of ¬†million years after a global disaster. | Q13: =IF(E13="", "", LEFT(E13, 1) * 1) -> 3 | R13: =IF(F13="","",VALUE(LEFT(F13,FIND(" ",F13)-1))) -> 2 | S13: =IF(G13="","",VALUE(LEFT(G13,FIND(" ",G13)-1))) -> 3 | T13: =IF(H13="","",VALUE(LEFT(H13,FIND(" ",H13)-1))) -> 3 | U13: 1000 | V13: =IF(L13="",0,IF(ISNUMBER(SEARCH("Bathroom",L13)),1,0)) -> 0 | W13: =IF(L13="",0,IF(ISNUMBER(SEARCH("Dining room",L13)),1,0)) -> 0 | X13: =IF(L13="",0,IF(ISNUMBER(SEARCH("Office",L13)),1,0)) -> 0 | Y13: =IF(L13="",0,IF(ISNUMBER(SEARCH("Bedroom",L13)),1,0)) -> 1 | Z13: =IF(L13="",0,IF(ISNUMBER(SEARCH("Living room",L13)),1,0)) -> 0 | AA13: =IF(M13="",0, IF(ISNUMBER(SEARCH("By yourself",M13)), 1, 0)) -> 1 | AB13: =IF(M13="", 0, IF(ISNUMBER(SEARCH("Friends", M13)), 1, 0)) -> 1 | AC13: =IF(M13="",0,IF(ISNUMBER(SEARCH("Family members", M13)), 1, 0)) -> 1 | AD13: =IF(M13="", 0, IF(ISNUMBER(SEARCH("Coworkers/Classmates", M13)), 1, 0)) -> 0 | AE13: =IF(M13="", 0, IF(ISNUMBER(SEARCH("Strangers", M13)), 1, 0)) -> 0 | AF13: =IF(N13="", 0, IF(ISNUMBER(SEARCH("Spring", N13)), 1, 0)) -> 0 | AG13: =IF(N13="", 0, IF(ISNUMBER(SEARCH("Summer", N13)), 1, 0)) -> 0 | AH13: =IF(N13="", 0, IF(ISNUMBER(SEARCH("Fall", N13)), 1, 0)) -> 1 | AI13: =IF(N13="", 0, IF(ISNUMBER(SEARCH("Winter", N13)), 1, 0)) -> 0
A14: 13 | B14: The Persistence of Memory | C14: 7 | D14: I feel shocked and discomfort. | E14: 5 - Strongly agree | F14: 1 - Strongly disagree | G14: 2 - Disagree | H14: 5 - Strongly agree | I14: 7 | J14: 8 | K14: 5 000 000$ | L14: Bedroom,Office | M14: Friends,Family members,By yourself | N14: Fall | O14: oreo | P14: A very solemn soundtrack. | Q14: =IF(E14="", "", LEFT(E14, 1) * 1) -> 5 | R14: =IF(F14="","",VALUE(LEFT(F14,FIND(" ",F14)-1))) -> 1 | S14: =IF(G14="","",VALUE(LEFT(G14,FIND(" ",G14)-1))) -> 2 | T14: =IF(H14="","",VALUE(LEFT(H14,FIND(" ",H14)-1))) -> 5 | U14: 5000000 | V14: =IF(L14="",0,IF(ISNUMBER(SEARCH("Bathroom",L14)),1,0)) -> 0 | W14: =IF(L14="",0,IF(ISNUMBER(SEARCH("Dining room",L14)),1,0)) -> 0 | X14: =IF(L14="",0,IF(ISNUMBER(SEARCH("Office",L14)),1,0)) -> 1 | Y14: =IF(L14="",0,IF(ISNUMBER(SEARCH("Bedroom",L14)),1,0)) -> 1 | Z14: =IF(L14="",0,IF(ISNUMBER(SEARCH("Living room",L14)),1,0)) -> 0 | AA14: =IF(M14="",0, IF(ISNUMBER(SEARCH("By yourself",M14)), 1, 0)) -> 1 | AB14: =IF(M14="", 0, IF(ISNUMBER(SEARCH("Friends", M14)), 1, 0)) -> 1 | AC14: =IF(M14="",0,IF(ISNUMBER(SEARCH("Family members", M14)), 1, 0)) -> 1 | AD14: =IF(M14="", 0, IF(ISNUMBER(SEARCH("Coworkers/Classmates", M14)), 1, 0)) -> 0 | AE14: =IF(M14="", 0, IF(ISNUMBER(SEARCH("Strangers", M14)), 1, 0)) -> 0 | AF14: =IF(N14="", 0, IF(ISNUMBER(SEARCH("Spring", N14)), 1, 0)) -> 0 | AG14: =IF(N14="", 0, IF(ISNUMBER(SEARCH("Summer", N14)), 1, 0)) -> 0 | AH14: =IF(N14="", 0, IF(ISNUMBER(SEARCH("Fall", N14)), 1, 0)) -> 1 | AI14: =IF(N14="", 0, IF(ISNUMBER(SEARCH("Winter", N14)), 1, 0)) -> 0
A15: 14 | B15: The Persistence of Memory | C15: 6 | D15: The painting makes me feel nostalgic and sad. The sunset conveys a calming ending feeling while the clocks melting away induces a feeling of the duration and longing where time loses its meaning. While it conveys to me of the inevitable passing of my limited amount of time, it also reminds me of the greatest times and memories I have experienced in my life. | E15: 4 - Agree | F15: 3 - Neutral/Unsure | G15: 4 - Agree | H15: 4 - Agree | I15: 5 | J15: 3 | K15: 100000 | L15: Living room,Dining room | M15: Friends,Strangers,By yourself | N15: Summer,Fall | O15: A chocolate dessert | P15: Slow, calm rhythm. No intense variations in melody. Strongly harmonic. | Q15: =IF(E15="", "", LEFT(E15, 1) * 1) -> 4 | R15: =IF(F15="","",VALUE(LEFT(F15,FIND(" ",F15)-1))) -> 3 | S15: =IF(G15="","",VALUE(LEFT(G15,FIND(" ",G15)-1))) -> 4 | T15: =IF(H15="","",VALUE(LEFT(H15,FIND(" ",H15)-1))) -> 4 | U15: 100000 | V15: =IF(L15="",0,IF(ISNUMBER(SEARCH("Bathroom",L15)),1,0)) -> 0 | W15: =IF(L15="",0,IF(ISNUMBER(SEARCH("Dining room",L15)),1,0)) -> 1 | X15: =IF(L15="",0,IF(ISNUMBER(SEARCH("Office",L15)),1,0)) -> 0 | Y15: =IF(L15="",0,IF(ISNUMBER(SEARCH("Bedroom",L15)),1,0)) -> 0 | Z15: =IF(L15="",0,IF(ISNUMBER(SEARCH("Living room",L15)),1,0)) -> 1 | AA15: =IF(M15="",0, IF(ISNUMBER(SEARCH("By yourself",M15)), 1, 0)) -> 1 | AB15: =IF(M15="", 0, IF(ISNUMBER(SEARCH("Friends", M15)), 1, 0)) -> 1 | AC15: =IF(M15="",0,IF(ISNUMBER(SEARCH("Family members", M15)), 1, 0)) -> 0 | AD15: =IF(M15="", 0, IF(ISNUMBER(SEARCH("Coworkers/Classmates", M15)), 1, 0)) -> 0 | AE15: =IF(M15="", 0, IF(ISNUMBER(SEARCH("Strangers", M15)), 1, 0)) -> 1 | AF15: =IF(N15="", 0, IF(ISNUMBER(SEARCH("Spring", N15)), 1, 0)) -> 0 | AG15: =IF(N15="", 0, IF(ISNUMBER(SEARCH("Summer", N15)), 1, 0)) -> 1 | AH15: =IF(N15="", 0, IF(ISNUMBER(SEARCH("Fall", N15)), 1, 0)) -> 1 | AI15: =IF(N15="", 0, IF(ISNUMBER(SEARCH("Winter", N15)), 1, 0)) -> 0
A16: 15 | B16: The Persistence of Memory | C16: 3 | D16: It makes me feel a bit anxious or sad since it seems to symbolize time melting away. | E16: 4 - Agree | F16: 3 - Neutral/Unsure | G16: 4 - Agree | H16: 1 - Strongly disagree | I16: 3 | J16: 5 | K16: 5000 | L16: Office | M16: By yourself | N16: Summer | O16: Scrambled eggs | P16: It would probably be slow and a little sad but not creepy or eerie. | Q16: =IF(E16="", "", LEFT(E16, 1) * 1) -> 4 | R16: =IF(F16="","",VALUE(LEFT(F16,FIND(" ",F16)-1))) -> 3 | S16: =IF(G16="","",VALUE(LEFT(G16,FIND(" ",G16)-1))) -> 4 | T16: =IF(H16="","",VALUE(LEFT(H16,FIND(" ",H16)-1))) -> 1 | U16: 5000 | V16: =IF(L16="",0,IF(ISNUMBER(SEARCH("Bathroom",L16)),1,0)) -> 0 | W16: =IF(L16="",0,IF(ISNUMBER(SEARCH("Dining room",L16)),1,0)) -> 0 | X16: =IF(L16="",0,IF(ISNUMBER(SEARCH("Office",L16)),1,0)) -> 1 | Y16: =IF(L16="",0,IF(ISNUMBER(SEARCH("Bedroom",L16)),1,0)) -> 0 | Z16: =IF(L16="",0,IF(ISNUMBER(SEARCH("Living room",L16)),1,0)) -> 0 | AA16: =IF(M16="",0, IF(ISNUMBER(SEARCH("By yourself",M16)), 1, 0)) -> 1 | AB16: =IF(M16="", 0, IF(ISNUMBER(SEARCH("Friends", M16)), 1, 0)) -> 0 | AC16: =IF(M16="",0,IF(ISNUMBER(SEARCH("Family members", M16)), 1, 0)) -> 0 | AD16: =IF(M16="", 0, IF(ISNUMBER(SEARCH("Coworkers/Classmates", M16)), 1, 0)) -> 0 | AE16: =IF(M16="", 0, IF(ISNUMBER(SEARCH("Strangers", M16)), 1, 0)) -> 0 | AF16: =IF(N16="", 0, IF(ISNUMBER(SEARCH("Spring", N16)), 1, 0)) -> 0 | AG16: =IF(N16="", 0, IF(ISNUMBER(SEARCH("Summer", N16)), 1, 0)) -> 1 | AH16: =IF(N16="", 0, IF(ISNUMBER(SEARCH("Fall", N16)), 1, 0)) -> 0 | AI16: =IF(N16="", 0, IF(ISNUMBER(SEARCH("Winter", N16)), 1, 0)) -> 0
A17: 16 | B17: The Persistence of Memory | C17: 8 | D17: This painting makes me feel a sense a fleeting emotions and temporality. I like the use of colour because as the sun sets, it makes me feel like there will be a tomorrow whilst grieving the today. | E17: 4 - Agree | F17: 3 - Neutral/Unsure | G17: 4 - Agree | H17: 2 - Disagree | I17: 4 | J17: 4 | K17: 1500000 | L17: Living room | M17: By yourself | N17: Fall | O17: Banana | P17: The soundtrack would be calm and serene. There's a weird uneasiness to it though, that things won't last and a feeling that you'll lose it all. | Q17: =IF(E17="", "", LEFT(E17, 1) * 1) -> 4 | R17: =IF(F17="","",VALUE(LEFT(F17,FIND(" ",F17)-1))) -> 3 | S17: =IF(G17="","",VALUE(LEFT(G17,FIND(" ",G17)-1))) -> 4 | T17: =IF(H17="","",VALUE(LEFT(H17,FIND(" ",H17)-1))) -> 2 | U17: 1500000 | V17: =IF(L17="",0,IF(ISNUMBER(SEARCH("Bathroom",L17)),1,0)) -> 0 | W17: =IF(L17="",0,IF(ISNUMBER(SEARCH("Dining room",L17)),1,0)) -> 0 | X17: =IF(L17="",0,IF(ISNUMBER(SEARCH("Office",L17)),1,0)) -> 0 | Y17: =IF(L17="",0,IF(ISNUMBER(SEARCH("Bedroom",L17)),1,0)) -> 0 | Z17: =IF(L17="",0,IF(ISNUMBER(SEARCH("Living room",L17)),1,0)) -> 1 | AA17: =IF(M17="",0, IF(ISNUMBER(SEARCH("By yourself",M17)), 1, 0)) -> 1 | AB17: =IF(M17="", 0, IF(ISNUMBER(SEARCH("Friends", M17)), 1, 0)) -> 0 | AC17: =IF(M17="",0,IF(ISNUMBER(SEARCH("Family members", M17)), 1, 0)) -> 0 | AD17: =IF(M17="", 0, IF(ISNUMBER(SEARCH("Coworkers/Classmates", M17)), 1, 0)) -> 0 | AE17: =IF(M17="", 0, IF(ISNUMBER(SEARCH("Strangers", M17)), 1, 0)) -> 0 | AF17: =IF(N17="", 0, IF(ISNUMBER(SEARCH("Spring", N17)), 1, 0)) -> 0 | AG17: =IF(N17="", 0, IF(ISNUMBER(SEARCH("Summer", N17)), 1, 0)) -> 0 | AH17: =IF(N17="", 0, IF(ISNUMBER(SEARCH("Fall", N17)), 1, 0)) -> 1 | AI17: =IF(N17="", 0, IF(ISNUMBER(SEARCH("Winter", N17)), 1, 0)) -> 0
A18: 17 | B18: The Persistence of Memory | C18: 8 | D18: This painting make me feel weird and little sad. Time look melting and nothing feel normal. It make me think life go fast. | E18: 4 - Agree | F18: 2 - Disagree | G18: 2 - Disagree | H18: 4 - Agree | I18: 5 | J18: 6 | K18: 50 | L18: Office | M18: By yourself | N18: Summer | O18: Old cheese that stay too long | P18: The soundtrack is very slow and quiet. Sound feel empty and long. Notes stretch and feel tired, like waiting and nothing happen. Music feel lonely and strange. | Q18: =IF(E18="", "", LEFT(E18, 1) * 1) -> 4 | R18: =IF(F18="","",VALUE(LEFT(F18,FIND(" ",F18)-1))) -> 2 | S18: =IF(G18="","",VALUE(LEFT(G18,FIND(" ",G18)-1))) -> 2 | T18: =IF(H18="","",VALUE(LEFT(H18,FIND(" ",H18)-1))) -> 4 | U18: 50 | V18: =IF(L18="",0,IF(ISNUMBER(SEARCH("Bathroom",L18)),1,0)) -> 0 | W18: =IF(L18="",0,IF(ISNUMBER(SEARCH("Dining room",L18)),1,0)) -> 0 | X18: =IF(L18="",0,IF(ISNUMBER(SEARCH("Office",L18)),1,0)) -> 1 | Y18: =IF(L18="",0,IF(ISNUMBER(SEARCH("Bedroom",L18)),1,0)) -> 0 | Z18: =IF(L18="",0,IF(ISNUMBER(SEARCH("Living room",L18)),1,0)) -> 0 | AA18: =IF(M18="",0, IF(ISNUMBER(SEARCH("By yourself",M18)), 1, 0)) -> 1 | AB18: =IF(M18="", 0, IF(ISNUMBER(SEARCH("Friends", M18)), 1, 0)) -> 0 | AC18: =IF(M18="",0,IF(ISNUMBER(SEARCH("Family members", M18)), 1, 0)) -> 0 | AD18: =IF(M18="", 0, IF(ISNUMBER(SEARCH("Coworkers/Classmates", M18)), 1, 0)) -> 0 | AE18: =IF(M18="", 0, IF(ISNUMBER(SEARCH("Strangers", M18)), 1, 0)) -> 0 | AF18: =IF(N18="", 0, IF(ISNUMBER(SEARCH("Spring", N18)), 1, 0)) -> 0 | AG18: =IF(N18="", 0, IF(ISNUMBER(SEARCH("Summer", N18)), 1, 0)) -> 1 | AH18: =IF(N18="", 0, IF(ISNUMBER(SEARCH("Fall", N18)), 1, 0)) -> 0 | AI18: =IF(N18="", 0, IF(ISNUMBER(SEARCH("Winter", N18)), 1, 0)) -> 0
A19: 18 | B19: The Persistence of Memory | C19: 9 | D19: It makes me feel lost and sad.¬† | E19: 5 - Strongly agree | F19: 2 - Disagree | G19: 3 - Neutral/Unsure | H19: 4 - Agree | I19: 3 | J19: 5 | K19: 200$ | L19: Office | M19: By yourself | N19: Fall | O19: coconut | P19: the soundtrack would be a violin piece. it would be slow but intense. | Q19: =IF(E19="", "", LEFT(E19, 1) * 1) -> 5 | R19: =IF(F19="","",VALUE(LEFT(F19,FIND(" ",F19)-1))) -> 2 | S19: =IF(G19="","",VALUE(LEFT(G19,FIND(" ",G19)-1))) -> 3 | T19: =IF(H19="","",VALUE(LEFT(H19,FIND(" ",H19)-1))) -> 4 | U19: 200 | V19: =IF(L19="",0,IF(ISNUMBER(SEARCH("Bathroom",L19)),1,0)) -> 0 | W19: =IF(L19="",0,IF(ISNUMBER(SEARCH("Dining room",L19)),1,0)) -> 0 | X19: =IF(L19="",0,IF(ISNUMBER(SEARCH("Office",L19)),1,0)) -> 1 | Y19: =IF(L19="",0,IF(ISNUMBER(SEARCH("Bedroom",L19)),1,0)) -> 0 | Z19: =IF(L19="",0,IF(ISNUMBER(SEARCH("Living room",L19)),1,0)) -> 0 | AA19: =IF(M19="",0, IF(ISNUMBER(SEARCH("By yourself",M19)), 1, 0)) -> 1 | AB19: =IF(M19="", 0, IF(ISNUMBER(SEARCH("Friends", M19)), 1, 0)) -> 0 | AC19: =IF(M19="",0,IF(ISNUMBER(SEARCH("Family members", M19)), 1, 0)) -> 0 | AD19: =IF(M19="", 0, IF(ISNUMBER(SEARCH("Coworkers/Classmates", M19)), 1, 0)) -> 0 | AE19: =IF(M19="", 0, IF(ISNUMBER(SEARCH("Strangers", M19)), 1, 0)) -> 0 | AF19: =IF(N19="", 0, IF(ISNUMBER(SEARCH("Spring", N19)), 1, 0)) -> 0 | AG19: =IF(N19="", 0, IF(ISNUMBER(SEARCH("Summer", N19)), 1, 0)) -> 0 | AH19: =IF(N19="", 0, IF(ISNUMBER(SEARCH("Fall", N19)), 1, 0)) -> 1 | AI19: =IF(N19="", 0, IF(ISNUMBER(SEARCH("Winter", N19)), 1, 0)) -> 0
A20: 19 | B20: The Persistence of Memory | C20: 3 | D20: Shocked, mysterious, unreal¬† | E20: 4 - Agree | F20: 1 - Strongly disagree | G20: 1 - Strongly disagree | H20: 4 - Agree | I20: 3 | J20: 6 | K20: 100 | L20: Dining room | M20: Strangers,By yourself | N20: Winter | O20: A single soft-boiled egg, yolk just barely holding together. | P20: Suspended, quietly unsettling. A single distant piano note drops into the air and lingers far longer than it should, as if streched. | Q20: =IF(E20="", "", LEFT(E20, 1) * 1) -> 4 | R20: =IF(F20="","",VALUE(LEFT(F20,FIND(" ",F20)-1))) -> 1 | S20: =IF(G20="","",VALUE(LEFT(G20,FIND(" ",G20)-1))) -> 1 | T20: =IF(H20="","",VALUE(LEFT(H20,FIND(" ",H20)-1))) -> 4 | U20: 100 | V20: =IF(L20="",0,IF(ISNUMBER(SEARCH("Bathroom",L20)),1,0)) -> 0 | W20: =IF(L20="",0,IF(ISNUMBER(SEARCH("Dining room",L20)),1,0)) -> 1 | X20: =IF(L20="",0,IF(ISNUMBER(SEARCH("Office",L20)),1,0)) -> 0 | Y20: =IF(L20="",0,IF(ISNUMBER(SEARCH("Bedroom",L20)),1,0)) -> 0 | Z20: =IF(L20="",0,IF(ISNUMBER(SEARCH("Living room",L20)),1,0)) -> 0 | AA20: =IF(M20="",0, IF(ISNUMBER(SEARCH("By yourself",M20)), 1, 0)) -> 1 | AB20: =IF(M20="", 0, IF(ISNUMBER(SEARCH("Friends", M20)), 1, 0)) -> 0 | AC20: =IF(M20="",0,IF(ISNUMBER(SEARCH("Family members", M20)), 1, 0)) -> 0 | AD20: =IF(M20="", 0, IF(ISNUMBER(SEARCH("Coworkers/Classmates", M20)), 1, 0)) -> 0 | AE20: =IF(M20="", 0, IF(ISNUMBER(SEARCH("Strangers", M20)), 1, 0)) -> 1 | AF20: =IF(N20="", 0, IF(ISNUMBER(SEARCH("Spring", N20)), 1, 0)) -> 0 | AG20: =IF(N20="", 0, IF(ISNUMBER(SEARCH("Summer", N20)), 1, 0)) -> 0 | AH20: =IF(N20="", 0, IF(ISNUMBER(SEARCH("Fall", N20)), 1, 0)) -> 0 | AI20: =IF(N20="", 0, IF(ISNUMBER(SEARCH("Winter", N20)), 1, 0)) -> 1
A21: 20 | B21: The Persistence of Memory | C21: 6 | D21: Very uneasy | E21: 4 - Agree | F21: 2 - Disagree | G21: 2 - Disagree | H21: 5 - Strongly agree | I21: 4 | J21: 3 | K21: 100 | L21: Office | M21: Coworkers/Classmates | N21: Fall | O21: Coffee | P21: Slow orchestral strings ensemble | Q21: =IF(E21="", "", LEFT(E21, 1) * 1) -> 4 | R21: =IF(F21="","",VALUE(LEFT(F21,FIND(" ",F21)-1))) -> 2 | S21: =IF(G21="","",VALUE(LEFT(G21,FIND(" ",G21)-1))) -> 2 | T21: =IF(H21="","",VALUE(LEFT(H21,FIND(" ",H21)-1))) -> 5 | U21: 100 | V21: =IF(L21="",0,IF(ISNUMBER(SEARCH("Bathroom",L21)),1,0)) -> 0 | W21: =IF(L21="",0,IF(ISNUMBER(SEARCH("Dining room",L21)),1,0)) -> 0 | X21: =IF(L21="",0,IF(ISNUMBER(SEARCH("Office",L21)),1,0)) -> 1 | Y21: =IF(L21="",0,IF(ISNUMBER(SEARCH("Bedroom",L21)),1,0)) -> 0 | Z21: =IF(L21="",0,IF(ISNUMBER(SEARCH("Living room",L21)),1,0)) -> 0 | AA21: =IF(M21="",0, IF(ISNUMBER(SEARCH("By yourself",M21)), 1, 0)) -> 0 | AB21: =IF(M21="", 0, IF(ISNUMBER(SEARCH("Friends", M21)), 1, 0)) -> 0 | AC21: =IF(M21="",0,IF(ISNUMBER(SEARCH("Family members", M21)), 1, 0)) -> 0 | AD21: =IF(M21="", 0, IF(ISNUMBER(SEARCH("Coworkers/Classmates", M21)), 1, 0)) -> 1 | AE21: =IF(M21="", 0, IF(ISNUMBER(SEARCH("Strangers", M21)), 1, 0)) -> 0 | AF21: =IF(N21="", 0, IF(ISNUMBER(SEARCH("Spring", N21)), 1, 0)) -> 0 | AG21: =IF(N21="", 0, IF(ISNUMBER(SEARCH("Summer", N21)), 1, 0)) -> 0 | AH21: =IF(N21="", 0, IF(ISNUMBER(SEARCH("Fall", N21)), 1, 0)) -> 1 | AI21: =IF(N21="", 0, IF(ISNUMBER(SEARCH("Winter", N21)), 1, 0)) -> 0
A22: 21 | B22: The Persistence of Memory | C22: 7 | D22: Perhaps the fragility of time as it passes so quickly. Seeing as the clocks are bended, one almost gets this feeling that the past also loses its importance or fades away as time moves forward. Overall, its sort of a weird feeling.¬† | E22: 4 - Agree | F22: 2 - Disagree | G22: 1 - Strongly disagree | H22: 4 - Agree | I22: 5 | J22: 3 | K22: 50 | L22: Living room | M22: Friends | N22: Winter | O22: Birthday cake | P22: The tides of history move forward and people either choose to stay caught in a specific tide or surf past it.¬† | Q22: =IF(E22="", "", LEFT(E22, 1) * 1) -> 4 | R22: =IF(F22="","",VALUE(LEFT(F22,FIND(" ",F22)-1))) -> 2 | S22: =IF(G22="","",VALUE(LEFT(G22,FIND(" ",G22)-1))) -> 1 | T22: =IF(H22="","",VALUE(LEFT(H22,FIND(" ",H22)-1))) -> 4 | U22: 50 | V22: =IF(L22="",0,IF(ISNUMBER(SEARCH("Bathroom",L22)),1,0)) -> 0 | W22: =IF(L22="",0,IF(ISNUMBER(SEARCH("Dining room",L22)),1,0)) -> 0 | X22: =IF(L22="",0,IF(ISNUMBER(SEARCH("Office",L22)),1,0)) -> 0 | Y22: =IF(L22="",0,IF(ISNUMBER(SEARCH("Bedroom",L22)),1,0)) -> 0 | Z22: =IF(L22="",0,IF(ISNUMBER(SEARCH("Living room",L22)),1,0)) -> 1 | AA22: =IF(M22="",0, IF(ISNUMBER(SEARCH("By yourself",M22)), 1, 0)) -> 0 | AB22: =IF(M22="", 0, IF(ISNUMBER(SEARCH("Friends", M22)), 1, 0)) -> 1 | AC22: =IF(M22="",0,IF(ISNUMBER(SEARCH("Family members", M22)), 1, 0)) -> 0 | AD22: =IF(M22="", 0, IF(ISNUMBER(SEARCH("Coworkers/Classmates", M22)), 1, 0)) -> 0 | AE22: =IF(M22="", 0, IF(ISNUMBER(SEARCH("Strangers", M22)), 1, 0)) -> 0 | AF22: =IF(N22="", 0, IF(ISNUMBER(SEARCH("Spring", N22)), 1, 0)) -> 0 | AG22: =IF(N22="", 0, IF(ISNUMBER(SEARCH("Summer", N22)), 1, 0)) -> 0 | AH22: =IF(N22="", 0, IF(ISNUMBER(SEARCH("Fall", N22)), 1, 0)) -> 0 | AI22: =IF(N22="", 0, IF(ISNUMBER(SEARCH("Winter", N22)), 1, 0)) -> 1
A23: 22 | B23: The Persistence of Memory | C23: 5 | D23: Ominous, it seems like the painting is trying to show how memory, even after years of time spending by, persists, and stays within ones body. | E23: 4 - Agree | F23: 2 - Disagree | G23: 3 - Neutral/Unsure | H23: 4 - Agree | I23: 8 | J23: 9 | K23: 50 | L23: Bedroom | M23: Friends | N23: Winter | O23: rotten tomato | P23: An orchestral soundtrack that commences with a very slow and sombre timbre and steadily keeps on increasing intensity and frequency till it reaches a dull minor scale peak, before descending back into silence. | Q23: =IF(E23="", "", LEFT(E23, 1) * 1) -> 4 | R23: =IF(F23="","",VALUE(LEFT(F23,FIND(" ",F23)-1))) -> 2 | S23: =IF(G23="","",VALUE(LEFT(G23,FIND(" ",G23)-1))) -> 3 | T23: =IF(H23="","",VALUE(LEFT(H23,FIND(" ",H23)-1))) -> 4 | U23: 50 | V23: =IF(L23="",0,IF(ISNUMBER(SEARCH("Bathroom",L23)),1,0)) -> 0 | W23: =IF(L23="",0,IF(ISNUMBER(SEARCH("Dining room",L23)),1,0)) -> 0 | X23: =IF(L23="",0,IF(ISNUMBER(SEARCH("Office",L23)),1,0)) -> 0 | Y23: =IF(L23="",0,IF(ISNUMBER(SEARCH("Bedroom",L23)),1,0)) -> 1 | Z23: =IF(L23="",0,IF(ISNUMBER(SEARCH("Living room",L23)),1,0)) -> 0 | AA23: =IF(M23="",0, IF(ISNUMBER(SEARCH("By yourself",M23)), 1, 0)) -> 0 | AB23: =IF(M23="", 0, IF(ISNUMBER(SEARCH("Friends", M23)), 1, 0)) -> 1 | AC23: =IF(M23="",0,IF(ISNUMBER(SEARCH("Family members", M23)), 1, 0)) -> 0 | AD23: =IF(M23="", 0, IF(ISNUMBER(SEARCH("Coworkers/Classmates", M23)), 1, 0)) -> 0 | AE23: =IF(M23="", 0, IF(ISNUMBER(SEARCH("Strangers", M23)), 1, 0)) -> 0 | AF23: =IF(N23="", 0, IF(ISNUMBER(SEARCH("Spring", N23)), 1, 0)) -> 0 | AG23: =IF(N23="", 0, IF(ISNUMBER(SEARCH("Summer", N23)), 1, 0)) -> 0 | AH23: =IF(N23="", 0, IF(ISNUMBER(SEARCH("Fall", N23)), 1, 0)) -> 0 | AI23: =IF(N23="", 0, IF(ISNUMBER(SEARCH("Winter", N23)), 1, 0)) -> 1
A24: 23 | B24: The Persistence of Memory | C24: 3 | D24: slowed down and lazy. | E24: 4 - Agree | F24: 2 - Disagree | G24: 2 - Disagree | H24: 5 - Strongly agree | I24: 5 | J24: 4 | K24: 50 | L24: Bathroom | M24: By yourself | N24: Winter | O24: cheesecake | P24: slowed classical | Q24: =IF(E24="", "", LEFT(E24, 1) * 1) -> 4 | R24: =IF(F24="","",VALUE(LEFT(F24,FIND(" ",F24)-1))) -> 2 | S24: =IF(G24="","",VALUE(LEFT(G24,FIND(" ",G24)-1))) -> 2 | T24: =IF(H24="","",VALUE(LEFT(H24,FIND(" ",H24)-1))) -> 5 | U24: 50 | V24: =IF(L24="",0,IF(ISNUMBER(SEARCH("Bathroom",L24)),1,0)) -> 1 | W24: =IF(L24="",0,IF(ISNUMBER(SEARCH("Dining room",L24)),1,0)) -> 0 | X24: =IF(L24="",0,IF(ISNUMBER(SEARCH("Office",L24)),1,0)) -> 0 | Y24: =IF(L24="",0,IF(ISNUMBER(SEARCH("Bedroom",L24)),1,0)) -> 0 | Z24: =IF(L24="",0,IF(ISNUMBER(SEARCH("Living room",L24)),1,0)) -> 0 | AA24: =IF(M24="",0, IF(ISNUMBER(SEARCH("By yourself",M24)), 1, 0)) -> 1 | AB24: =IF(M24="", 0, IF(ISNUMBER(SEARCH("Friends", M24)), 1, 0)) -> 0 | AC24: =IF(M24="",0,IF(ISNUMBER(SEARCH("Family members", M24)), 1, 0)) -> 0 | AD24: =IF(M24="", 0, IF(ISNUMBER(SEARCH("Coworkers/Classmates", M24)), 1, 0)) -> 0 | AE24: =IF(M24="", 0, IF(ISNUMBER(SEARCH("Strangers", M24)), 1, 0)) -> 0 | AF24: =IF(N24="", 0, IF(ISNUMBER(SEARCH("Spring", N24)), 1, 0)) -> 0 | AG24: =IF(N24="", 0, IF(ISNUMBER(SEARCH("Summer", N24)), 1, 0)) -> 0 | AH24: =IF(N24="", 0, IF(ISNUMBER(SEARCH("Fall", N24)), 1, 0)) -> 0 | AI24: =IF(N24="", 0, IF(ISNUMBER(SEARCH("Winter", N24)), 1, 0)) -> 1
A25: 24 | B25: The Persistence of Memory | C25: 5 | D25: This painting makes me feel a bit strange. The content in the painting goes against reality, and it feels like there are many elements of imagination and distortion. | E25: 3 - Neutral/Unsure | F25: 3 - Neutral/Unsure | G25: 3 - Neutral/Unsure | H25: 3 - Neutral/Unsure | I25: 5 | J25: 4 | K25: 100 | L25: Bedroom | M25: Family members | N25: Fall | O25: Sandwich | P25: It sounds a bit strange, fairly calm, and somewhat random. | Q25: =IF(E25="", "", LEFT(E25, 1) * 1) -> 3 | R25: =IF(F25="","",VALUE(LEFT(F25,FIND(" ",F25)-1))) -> 3 | S25: =IF(G25="","",VALUE(LEFT(G25,FIND(" ",G25)-1))) -> 3 | T25: =IF(H25="","",VALUE(LEFT(H25,FIND(" ",H25)-1))) -> 3 | U25: 100 | V25: =IF(L25="",0,IF(ISNUMBER(SEARCH("Bathroom",L25)),1,0)) -> 0 | W25: =IF(L25="",0,IF(ISNUMBER(SEARCH("Dining room",L25)),1,0)) -> 0 | X25: =IF(L25="",0,IF(ISNUMBER(SEARCH("Office",L25)),1,0)) -> 0 | Y25: =IF(L25="",0,IF(ISNUMBER(SEARCH("Bedroom",L25)),1,0)) -> 1 | Z25: =IF(L25="",0,IF(ISNUMBER(SEARCH("Living room",L25)),1,0)) -> 0 | AA25: =IF(M25="",0, IF(ISNUMBER(SEARCH("By yourself",M25)), 1, 0)) -> 0 | AB25: =IF(M25="", 0, IF(ISNUMBER(SEARCH("Friends", M25)), 1, 0)) -> 0 | AC25: =IF(M25="",0,IF(ISNUMBER(SEARCH("Family members", M25)), 1, 0)) -> 1 | AD25: =IF(M25="", 0, IF(ISNUMBER(SEARCH("Coworkers/Classmates", M25)), 1, 0)) -> 0 | AE25: =IF(M25="", 0, IF(ISNUMBER(SEARCH("Strangers", M25)), 1, 0)) -> 0 | AF25: =IF(N25="", 0, IF(ISNUMBER(SEARCH("Spring", N25)), 1, 0)) -> 0 | AG25: =IF(N25="", 0, IF(ISNUMBER(SEARCH("Summer", N25)), 1, 0)) -> 0 | AH25: =IF(N25="", 0, IF(ISNUMBER(SEARCH("Fall", N25)), 1, 0)) -> 1 | AI25: =IF(N25="", 0, IF(ISNUMBER(SEARCH("Winter", N25)), 1, 0)) -> 0
A26: 25 | B26: The Persistence of Memory | C26: 7 | D26: This painting makes me feel as though my life is becoming foggy and I am reflecting on life as it was in a better time. As if I can no longer dream and my time is running out in a bleak world where I can no longer return to the person I once was. | E26: 4 - Agree | F26: 2 - Disagree | G26: 2 - Disagree | H26: 4 - Agree | I26: 4 | J26: 7 | K26: 150 | L26: Bedroom,Bathroom | M26: By yourself | N26: Fall | O26: puffer fish | P26: A slightly joyous melody that starts off fast but slows down as the track goes on becoming sadder, with eerie background music that grows louder and faster until the end where the track abruptly stops. | Q26: =IF(E26="", "", LEFT(E26, 1) * 1) -> 4 | R26: =IF(F26="","",VALUE(LEFT(F26,FIND(" ",F26)-1))) -> 2 | S26: =IF(G26="","",VALUE(LEFT(G26,FIND(" ",G26)-1))) -> 2 | T26: =IF(H26="","",VALUE(LEFT(H26,FIND(" ",H26)-1))) -> 4 | U26: 150 | V26: =IF(L26="",0,IF(ISNUMBER(SEARCH("Bathroom",L26)),1,0)) -> 1 | W26: =IF(L26="",0,IF(ISNUMBER(SEARCH("Dining room",L26)),1,0)) -> 0 | X26: =IF(L26="",0,IF(ISNUMBER(SEARCH("Office",L26)),1,0)) -> 0 | Y26: =IF(L26="",0,IF(ISNUMBER(SEARCH("Bedroom",L26)),1,0)) -> 1 | Z26: =IF(L26="",0,IF(ISNUMBER(SEARCH("Living room",L26)),1,0)) -> 0 | AA26: =IF(M26="",0, IF(ISNUMBER(SEARCH("By yourself",M26)), 1, 0)) -> 1 | AB26: =IF(M26="", 0, IF(ISNUMBER(SEARCH("Friends", M26)), 1, 0)) -> 0 | AC26: =IF(M26="",0,IF(ISNUMBER(SEARCH("Family members", M26)), 1, 0)) -> 0 | AD26: =IF(M26="", 0, IF(ISNUMBER(SEARCH("Coworkers/Classmates", M26)), 1, 0)) -> 0 | AE26: =IF(M26="", 0, IF(ISNUMBER(SEARCH("Strangers", M26)), 1, 0)) -> 0 | AF26: =IF(N26="", 0, IF(ISNUMBER(SEARCH("Spring", N26)), 1, 0)) -> 0 | AG26: =IF(N26="", 0, IF(ISNUMBER(SEARCH("Summer", N26)), 1, 0)) -> 0 | AH26: =IF(N26="", 0, IF(ISNUMBER(SEARCH("Fall", N26)), 1, 0)) -> 1 | AI26: =IF(N26="", 0, IF(ISNUMBER(SEARCH("Winter", N26)), 1, 0)) -> 0
A27: 26 | B27: The Persistence of Memory | C27: 4 | D27: Uncanny, lonely, still, anxious | E27: 5 - Strongly agree | F27: 2 - Disagree | G27: 2 - Disagree | H27: 4 - Agree | I27: 3 | J27: 8 | K27: 100 | L27: Bathroom,Office,Living room | M27: Friends,Family members | N27: Summer,Fall | O27: Cheesecake | P27: A low, steady hum and a long, shaking whistle and the static of radio. | Q27: =IF(E27="", "", LEFT(E27, 1) * 1) -> 5 | R27: =IF(F27="","",VALUE(LEFT(F27,FIND(" ",F27)-1))) -> 2 | S27: =IF(G27="","",VALUE(LEFT(G27,FIND(" ",G27)-1))) -> 2 | T27: =IF(H27="","",VALUE(LEFT(H27,FIND(" ",H27)-1))) -> 4 | U27: 100 | V27: =IF(L27="",0,IF(ISNUMBER(SEARCH("Bathroom",L27)),1,0)) -> 1 | W27: =IF(L27="",0,IF(ISNUMBER(SEARCH("Dining room",L27)),1,0)) -> 0 | X27: =IF(L27="",0,IF(ISNUMBER(SEARCH("Office",L27)),1,0)) -> 1 | Y27: =IF(L27="",0,IF(ISNUMBER(SEARCH("Bedroom",L27)),1,0)) -> 0 | Z27: =IF(L27="",0,IF(ISNUMBER(SEARCH("Living room",L27)),1,0)) -> 1 | AA27: =IF(M27="",0, IF(ISNUMBER(SEARCH("By yourself",M27)), 1, 0)) -> 0 | AB27: =IF(M27="", 0, IF(ISNUMBER(SEARCH("Friends", M27)), 1, 0)) -> 1 | AC27: =IF(M27="",0,IF(ISNUMBER(SEARCH("Family members", M27)), 1, 0)) -> 1 | AD27: =IF(M27="", 0, IF(ISNUMBER(SEARCH("Coworkers/Classmates", M27)), 1, 0)) -> 0 | AE27: =IF(M27="", 0, IF(ISNUMBER(SEARCH("Strangers", M27)), 1, 0)) -> 0 | AF27: =IF(N27="", 0, IF(ISNUMBER(SEARCH("Spring", N27)), 1, 0)) -> 0 | AG27: =IF(N27="", 0, IF(ISNUMBER(SEARCH("Summer", N27)), 1, 0)) -> 1 | AH27: =IF(N27="", 0, IF(ISNUMBER(SEARCH("Fall", N27)), 1, 0)) -> 1 | AI27: =IF(N27="", 0, IF(ISNUMBER(SEARCH("Winter", N27)), 1, 0)) -> 0
A28: 27 | B28: The Persistence of Memory | C28: 7 | D28: Sad, uncertain, slightly disoriented. | E28: 4 - Agree | F28: 1 - Strongly disagree | G28: 2 - Disagree | H28: 5 - Strongly agree | I28: 6 | J28: 5 | K28: I don't like feeling uneasy so I wouldn't pay much, maybe $10 | L28: Bathroom,Office | M28: Friends,Family members | N28: Summer | O28: Poutine | P28: I'd imagine a very sombre soundtrack, something that would play in a movie after a very beloved character dies. | Q28: =IF(E28="", "", LEFT(E28, 1) * 1) -> 4 | R28: =IF(F28="","",VALUE(LEFT(F28,FIND(" ",F28)-1))) -> 1 | S28: =IF(G28="","",VALUE(LEFT(G28,FIND(" ",G28)-1))) -> 2 | T28: =IF(H28="","",VALUE(LEFT(H28,FIND(" ",H28)-1))) -> 5 | U28: 10 | V28: =IF(L28="",0,IF(ISNUMBER(SEARCH("Bathroom",L28)),1,0)) -> 1 | W28: =IF(L28="",0,IF(ISNUMBER(SEARCH("Dining room",L28)),1,0)) -> 0 | X28: =IF(L28="",0,IF(ISNUMBER(SEARCH("Office",L28)),1,0)) -> 1 | Y28: =IF(L28="",0,IF(ISNUMBER(SEARCH("Bedroom",L28)),1,0)) -> 0 | Z28: =IF(L28="",0,IF(ISNUMBER(SEARCH("Living room",L28)),1,0)) -> 0 | AA28: =IF(M28="",0, IF(ISNUMBER(SEARCH("By yourself",M28)), 1, 0)) -> 0 | AB28: =IF(M28="", 0, IF(ISNUMBER(SEARCH("Friends", M28)), 1, 0)) -> 1 | AC28: =IF(M28="",0,IF(ISNUMBER(SEARCH("Family members", M28)), 1, 0)) -> 1 | AD28: =IF(M28="", 0, IF(ISNUMBER(SEARCH("Coworkers/Classmates", M28)), 1, 0)) -> 0 | AE28: =IF(M28="", 0, IF(ISNUMBER(SEARCH("Strangers", M28)), 1, 0)) -> 0 | AF28: =IF(N28="", 0, IF(ISNUMBER(SEARCH("Spring", N28)), 1, 0)) -> 0 | AG28: =IF(N28="", 0, IF(ISNUMBER(SEARCH("Summer", N28)), 1, 0)) -> 1 | AH28: =IF(N28="", 0, IF(ISNUMBER(SEARCH("Fall", N28)), 1, 0)) -> 0 | AI28: =IF(N28="", 0, IF(ISNUMBER(SEARCH("Winter", N28)), 1, 0)) -> 0
A29: 28 | B29: The Persistence of Memory | C29: 6 | D29: Uneasy since time in this picture doesn't seem to be a rigid construct | E29: 4 - Agree | F29: 3 - Neutral/Unsure | G29: 2 - Disagree | H29: 4 - Agree | I29: 7 | J29: 8 | K29: 50 | L29: Office,Living room | M29: Strangers,By yourself | N29: Summer | O29: cheese sandwich¬† | P29: slow dramatic violin notes¬† | Q29: =IF(E29="", "", LEFT(E29, 1) * 1) -> 4 | R29: =IF(F29="","",VALUE(LEFT(F29,FIND(" ",F29)-1))) -> 3 | S29: =IF(G29="","",VALUE(LEFT(G29,FIND(" ",G29)-1))) -> 2 | T29: =IF(H29="","",VALUE(LEFT(H29,FIND(" ",H29)-1))) -> 4 | U29: 50 | V29: =IF(L29="",0,IF(ISNUMBER(SEARCH("Bathroom",L29)),1,0)) -> 0 | W29: =IF(L29="",0,IF(ISNUMBER(SEARCH("Dining room",L29)),1,0)) -> 0 | X29: =IF(L29="",0,IF(ISNUMBER(SEARCH("Office",L29)),1,0)) -> 1 | Y29: =IF(L29="",0,IF(ISNUMBER(SEARCH("Bedroom",L29)),1,0)) -> 0 | Z29: =IF(L29="",0,IF(ISNUMBER(SEARCH("Living room",L29)),1,0)) -> 1 | AA29: =IF(M29="",0, IF(ISNUMBER(SEARCH("By yourself",M29)), 1, 0)) -> 1 | AB29: =IF(M29="", 0, IF(ISNUMBER(SEARCH("Friends", M29)), 1, 0)) -> 0 | AC29: =IF(M29="",0,IF(ISNUMBER(SEARCH("Family members", M29)), 1, 0)) -> 0 | AD29: =IF(M29="", 0, IF(ISNUMBER(SEARCH("Coworkers/Classmates", M29)), 1, 0)) -> 0 | AE29: =IF(M29="", 0, IF(ISNUMBER(SEARCH("Strangers", M29)), 1, 0)) -> 1 | AF29: =IF(N29="", 0, IF(ISNUMBER(SEARCH("Spring", N29)), 1, 0)) -> 0 | AG29: =IF(N29="", 0, IF(ISNUMBER(SEARCH("Summer", N29)), 1, 0)) -> 1 | AH29: =IF(N29="", 0, IF(ISNUMBER(SEARCH("Fall", N29)), 1, 0)) -> 0 | AI29: =IF(N29="", 0, IF(ISNUMBER(SEARCH("Winter", N29)), 1, 0)) -> 0
A30: 29 | B30: The Persistence of Memory | C30: 8 | D30: It makes me feel sad and drowsy. | E30: 4 - Agree | F30: 2 - Disagree | G30: 3 - Neutral/Unsure | H30: 4 - Agree | I30: 5 | J30: 8 | K30: 1000 | L30: Living room | M30: Friends,By yourself | N30: Fall | O30: Mashed Potatoes. | P30: Slow jazz. | Q30: =IF(E30="", "", LEFT(E30, 1) * 1) -> 4 | R30: =IF(F30="","",VALUE(LEFT(F30,FIND(" ",F30)-1))) -> 2 | S30: =IF(G30="","",VALUE(LEFT(G30,FIND(" ",G30)-1))) -> 3 | T30: =IF(H30="","",VALUE(LEFT(H30,FIND(" ",H30)-1))) -> 4 | U30: 1000 | V30: =IF(L30="",0,IF(ISNUMBER(SEARCH("Bathroom",L30)),1,0)) -> 0 | W30: =IF(L30="",0,IF(ISNUMBER(SEARCH("Dining room",L30)),1,0)) -> 0 | X30: =IF(L30="",0,IF(ISNUMBER(SEARCH("Office",L30)),1,0)) -> 0 | Y30: =IF(L30="",0,IF(ISNUMBER(SEARCH("Bedroom",L30)),1,0)) -> 0 | Z30: =IF(L30="",0,IF(ISNUMBER(SEARCH("Living room",L30)),1,0)) -> 1 | AA30: =IF(M30="",0, IF(ISNUMBER(SEARCH("By yourself",M30)), 1, 0)) -> 1 | AB30: =IF(M30="", 0, IF(ISNUMBER(SEARCH("Friends", M30)), 1, 0)) -> 1 | AC30: =IF(M30="",0,IF(ISNUMBER(SEARCH("Family members", M30)), 1, 0)) -> 0 | AD30: =IF(M30="", 0, IF(ISNUMBER(SEARCH("Coworkers/Classmates", M30)), 1, 0)) -> 0 | AE30: =IF(M30="", 0, IF(ISNUMBER(SEARCH("Strangers", M30)), 1, 0)) -> 0 | AF30: =IF(N30="", 0, IF(ISNUMBER(SEARCH("Spring", N30)), 1, 0)) -> 0 | AG30: =IF(N30="", 0, IF(ISNUMBER(SEARCH("Summer", N30)), 1, 0)) -> 0 | AH30: =IF(N30="", 0, IF(ISNUMBER(SEARCH("Fall", N30)), 1, 0)) -> 1 | AI30: =IF(N30="", 0, IF(ISNUMBER(SEARCH("Winter", N30)), 1, 0)) -> 0
A31: 30 | B31: The Persistence of Memory | C31: 10 | D31: This painting makes me feel sad and feel like I am running out of time | E31: 5 - Strongly agree | F31: 1 - Strongly disagree | G31: 1 - Strongly disagree | H31: 5 - Strongly agree | I31: 2 | J31: 3 | K31: 300 | L31: Dining room | M31: By yourself | N31: Fall | O31: Soup | P31: Slow and sad music played by a violine of a cello. Burns the Heart | Q31: =IF(E31="", "", LEFT(E31, 1) * 1) -> 5 | R31: =IF(F31="","",VALUE(LEFT(F31,FIND(" ",F31)-1))) -> 1 | S31: =IF(G31="","",VALUE(LEFT(G31,FIND(" ",G31)-1))) -> 1 | T31: =IF(H31="","",VALUE(LEFT(H31,FIND(" ",H31)-1))) -> 5 | U31: 300 | V31: =IF(L31="",0,IF(ISNUMBER(SEARCH("Bathroom",L31)),1,0)) -> 0 | W31: =IF(L31="",0,IF(ISNUMBER(SEARCH("Dining room",L31)),1,0)) -> 1 | X31: =IF(L31="",0,IF(ISNUMBER(SEARCH("Office",L31)),1,0)) -> 0 | Y31: =IF(L31="",0,IF(ISNUMBER(SEARCH("Bedroom",L31)),1,0)) -> 0 | Z31: =IF(L31="",0,IF(ISNUMBER(SEARCH("Living room",L31)),1,0)) -> 0 | AA31: =IF(M31="",0, IF(ISNUMBER(SEARCH("By yourself",M31)), 1, 0)) -> 1 | AB31: =IF(M31="", 0, IF(ISNUMBER(SEARCH("Friends", M31)), 1, 0)) -> 0 | AC31: =IF(M31="",0,IF(ISNUMBER(SEARCH("Family members", M31)), 1, 0)) -> 0 | AD31: =IF(M31="", 0, IF(ISNUMBER(SEARCH("Coworkers/Classmates", M31)), 1, 0)) -> 0 | AE31: =IF(M31="", 0, IF(ISNUMBER(SEARCH("Strangers", M31)), 1, 0)) -> 0 | AF31: =IF(N31="", 0, IF(ISNUMBER(SEARCH("Spring", N31)), 1, 0)) -> 0 | AG31: =IF(N31="", 0, IF(ISNUMBER(SEARCH("Summer", N31)), 1, 0)) -> 0 | AH31: =IF(N31="", 0, IF(ISNUMBER(SEARCH("Fall", N31)), 1, 0)) -> 1 | AI31: =IF(N31="", 0, IF(ISNUMBER(SEARCH("Winter", N31)), 1, 0)) -> 0
A32: 31 | B32: The Persistence of Memory | C32: 5 | D32: Old, lonely¬† | E32: 3 - Neutral/Unsure | F32: 2 - Disagree | G32: 3 - Neutral/Unsure | H32: 4 - Agree | I32: 5 | J32: 3 | K32: 1 | L32: Bathroom | M32: Strangers,By yourself | N32: Fall | O32: Bread | P32: Slow music | Q32: =IF(E32="", "", LEFT(E32, 1) * 1) -> 3 | R32: =IF(F32="","",VALUE(LEFT(F32,FIND(" ",F32)-1))) -> 2 | S32: =IF(G32="","",VALUE(LEFT(G32,FIND(" ",G32)-1))) -> 3 | T32: =IF(H32="","",VALUE(LEFT(H32,FIND(" ",H32)-1))) -> 4 | U32: 1 | V32: =IF(L32="",0,IF(ISNUMBER(SEARCH("Bathroom",L32)),1,0)) -> 1 | W32: =IF(L32="",0,IF(ISNUMBER(SEARCH("Dining room",L32)),1,0)) -> 0 | X32: =IF(L32="",0,IF(ISNUMBER(SEARCH("Office",L32)),1,0)) -> 0 | Y32: =IF(L32="",0,IF(ISNUMBER(SEARCH("Bedroom",L32)),1,0)) -> 0 | Z32: =IF(L32="",0,IF(ISNUMBER(SEARCH("Living room",L32)),1,0)) -> 0 | AA32: =IF(M32="",0, IF(ISNUMBER(SEARCH("By yourself",M32)), 1, 0)) -> 1 | AB32: =IF(M32="", 0, IF(ISNUMBER(SEARCH("Friends", M32)), 1, 0)) -> 0 | AC32: =IF(M32="",0,IF(ISNUMBER(SEARCH("Family members", M32)), 1, 0)) -> 0 | AD32: =IF(M32="", 0, IF(ISNUMBER(SEARCH("Coworkers/Classmates", M32)), 1, 0)) -> 0 | AE32: =IF(M32="", 0, IF(ISNUMBER(SEARCH("Strangers", M32)), 1, 0)) -> 1 | AF32: =IF(N32="", 0, IF(ISNUMBER(SEARCH("Spring", N32)), 1, 0)) -> 0 | AG32: =IF(N32="", 0, IF(ISNUMBER(SEARCH("Summer", N32)), 1, 0)) -> 0 | AH32: =IF(N32="", 0, IF(ISNUMBER(SEARCH("Fall", N32)), 1, 0)) -> 1 | AI32: =IF(N32="", 0, IF(ISNUMBER(SEARCH("Winter", N32)), 1, 0)) -> 0
A33: 32 | B33: The Persistence of Memory | C33: 4 | D33: This painting makes me feel cognizant of the connection between and relativity of space and time. | E33: 4 - Agree | F33: 2 - Disagree | G33: 2 - Disagree | H33: 4 - Agree | I33: 5 | J33: 9 | K33: 20 | L33: Office | M33: By yourself | N33: Summer | O33: Bitter melon | P33: The soundtrack would be slow, contemplative, maybe even a little experimental at times. | Q33: =IF(E33="", "", LEFT(E33, 1) * 1) -> 4 | R33: =IF(F33="","",VALUE(LEFT(F33,FIND(" ",F33)-1))) -> 2 | S33: =IF(G33="","",VALUE(LEFT(G33,FIND(" ",G33)-1))) -> 2 | T33: =IF(H33="","",VALUE(LEFT(H33,FIND(" ",H33)-1))) -> 4 | U33: 20 | V33: =IF(L33="",0,IF(ISNUMBER(SEARCH("Bathroom",L33)),1,0)) -> 0 | W33: =IF(L33="",0,IF(ISNUMBER(SEARCH("Dining room",L33)),1,0)) -> 0 | X33: =IF(L33="",0,IF(ISNUMBER(SEARCH("Office",L33)),1,0)) -> 1 | Y33: =IF(L33="",0,IF(ISNUMBER(SEARCH("Bedroom",L33)),1,0)) -> 0 | Z33: =IF(L33="",0,IF(ISNUMBER(SEARCH("Living room",L33)),1,0)) -> 0 | AA33: =IF(M33="",0, IF(ISNUMBER(SEARCH("By yourself",M33)), 1, 0)) -> 1 | AB33: =IF(M33="", 0, IF(ISNUMBER(SEARCH("Friends", M33)), 1, 0)) -> 0 | AC33: =IF(M33="",0,IF(ISNUMBER(SEARCH("Family members", M33)), 1, 0)) -> 0 | AD33: =IF(M33="", 0, IF(ISNUMBER(SEARCH("Coworkers/Classmates", M33)), 1, 0)) -> 0 | AE33: =IF(M33="", 0, IF(ISNUMBER(SEARCH("Strangers", M33)), 1, 0)) -> 0 | AF33: =IF(N33="", 0, IF(ISNUMBER(SEARCH("Spring", N33)), 1, 0)) -> 0 | AG33: =IF(N33="", 0, IF(ISNUMBER(SEARCH("Summer", N33)), 1, 0)) -> 1 | AH33: =IF(N33="", 0, IF(ISNUMBER(SEARCH("Fall", N33)), 1, 0)) -> 0 | AI33: =IF(N33="", 0, IF(ISNUMBER(SEARCH("Winter", N33)), 1, 0)) -> 0
A34: 33 | B34: The Persistence of Memory | C34: 8 | D34: The painting makes me feel a sense of longing, almost as if time is passing as symbolized by the clocks melting. Accompanied by this, it also makes me feel a sense of urgency since I recognize that time is passing so I feel like I should be doing more with my time!¬† | E34: 5 - Strongly agree | F34: 2 - Disagree | G34: 2 - Disagree | H34: 3 - Neutral/Unsure | I34: 3 | J34: 4 | K34: 50 | L34: Office | M34: Friends,Strangers,By yourself | N34: Fall,Winter | O34: Pizza | P34: Slow brass instruments, trumpets, playing in minor key, lower register notes.¬† | Q34: =IF(E34="", "", LEFT(E34, 1) * 1) -> 5 | R34: =IF(F34="","",VALUE(LEFT(F34,FIND(" ",F34)-1))) -> 2 | S34: =IF(G34="","",VALUE(LEFT(G34,FIND(" ",G34)-1))) -> 2 | T34: =IF(H34="","",VALUE(LEFT(H34,FIND(" ",H34)-1))) -> 3 | U34: 50 | V34: =IF(L34="",0,IF(ISNUMBER(SEARCH("Bathroom",L34)),1,0)) -> 0 | W34: =IF(L34="",0,IF(ISNUMBER(SEARCH("Dining room",L34)),1,0)) -> 0 | X34: =IF(L34="",0,IF(ISNUMBER(SEARCH("Office",L34)),1,0)) -> 1 | Y34: =IF(L34="",0,IF(ISNUMBER(SEARCH("Bedroom",L34)),1,0)) -> 0 | Z34: =IF(L34="",0,IF(ISNUMBER(SEARCH("Living room",L34)),1,0)) -> 0 | AA34: =IF(M34="",0, IF(ISNUMBER(SEARCH("By yourself",M34)), 1, 0)) -> 1 | AB34: =IF(M34="", 0, IF(ISNUMBER(SEARCH("Friends", M34)), 1, 0)) -> 1 | AC34: =IF(M34="",0,IF(ISNUMBER(SEARCH("Family members", M34)), 1, 0)) -> 0 | AD34: =IF(M34="", 0, IF(ISNUMBER(SEARCH("Coworkers/Classmates", M34)), 1, 0)) -> 0 | AE34: =IF(M34="", 0, IF(ISNUMBER(SEARCH("Strangers", M34)), 1, 0)) -> 1 | AF34: =IF(N34="", 0, IF(ISNUMBER(SEARCH("Spring", N34)), 1, 0)) -> 0 | AG34: =IF(N34="", 0, IF(ISNUMBER(SEARCH("Summer", N34)), 1, 0)) -> 0 | AH34: =IF(N34="", 0, IF(ISNUMBER(SEARCH("Fall", N34)), 1, 0)) -> 1 | AI34: =IF(N34="", 0, IF(ISNUMBER(SEARCH("Winter", N34)), 1, 0)) -> 1
A35: 34 | B35: The Persistence of Memory | C35: 7 | D35: It makes me feel slightly uneasy but also calm at the same time. The scene feels quiet and almost frozen, like everything is happening very slowly or outside of normal time. | E35: 3 - Neutral/Unsure | F35: 1 - Strongly disagree | G35: 4 - Agree | H35: 4 - Agree | I35: 5 | J35: 5 | K35: 500 | L35: Office | M35: By yourself | N35: Winter | O35: I can't imagine it as a food. | P35: The soundtrack would be very slow and minimal, with long stretches of silence between soft, drawn-out sounds. | Q35: =IF(E35="", "", LEFT(E35, 1) * 1) -> 3 | R35: =IF(F35="","",VALUE(LEFT(F35,FIND(" ",F35)-1))) -> 1 | S35: =IF(G35="","",VALUE(LEFT(G35,FIND(" ",G35)-1))) -> 4 | T35: =IF(H35="","",VALUE(LEFT(H35,FIND(" ",H35)-1))) -> 4 | U35: 500 | V35: =IF(L35="",0,IF(ISNUMBER(SEARCH("Bathroom",L35)),1,0)) -> 0 | W35: =IF(L35="",0,IF(ISNUMBER(SEARCH("Dining room",L35)),1,0)) -> 0 | X35: =IF(L35="",0,IF(ISNUMBER(SEARCH("Office",L35)),1,0)) -> 1 | Y35: =IF(L35="",0,IF(ISNUMBER(SEARCH("Bedroom",L35)),1,0)) -> 0 | Z35: =IF(L35="",0,IF(ISNUMBER(SEARCH("Living room",L35)),1,0)) -> 0 | AA35: =IF(M35="",0, IF(ISNUMBER(SEARCH("By yourself",M35)), 1, 0)) -> 1 | AB35: =IF(M35="", 0, IF(ISNUMBER(SEARCH("Friends", M35)), 1, 0)) -> 0 | AC35: =IF(M35="",0,IF(ISNUMBER(SEARCH("Family members", M35)), 1, 0)) -> 0 | AD35: =IF(M35="", 0, IF(ISNUMBER(SEARCH("Coworkers/Classmates", M35)), 1, 0)) -> 0 | AE35: =IF(M35="", 0, IF(ISNUMBER(SEARCH("Strangers", M35)), 1, 0)) -> 0 | AF35: =IF(N35="", 0, IF(ISNUMBER(SEARCH("Spring", N35)), 1, 0)) -> 0 | AG35: =IF(N35="", 0, IF(ISNUMBER(SEARCH("Summer", N35)), 1, 0)) -> 0 | AH35: =IF(N35="", 0, IF(ISNUMBER(SEARCH("Fall", N35)), 1, 0)) -> 0 | AI35: =IF(N35="", 0, IF(ISNUMBER(SEARCH("Winter", N35)), 1, 0)) -> 1
A36: 35 | B36: The Persistence of Memory | C36: 1 | D36: Strange, repressed | E36: 5 - Strongly agree | F36: 1 - Strongly disagree | G36: 3 - Neutral/Unsure | H36: 4 - Agree | I36: 3 | J36: 5 | K36: 3.14 | L36: Office | M36: Family members,By yourself | N36: Fall | O36: expired but unmelted ice cream | P36: The sound produced by the continuous vibration of metal | Q36: =IF(E36="", "", LEFT(E36, 1) * 1) -> 5 | R36: =IF(F36="","",VALUE(LEFT(F36,FIND(" ",F36)-1))) -> 1 | S36: =IF(G36="","",VALUE(LEFT(G36,FIND(" ",G36)-1))) -> 3 | T36: =IF(H36="","",VALUE(LEFT(H36,FIND(" ",H36)-1))) -> 4 | U36: 3.14 | V36: =IF(L36="",0,IF(ISNUMBER(SEARCH("Bathroom",L36)),1,0)) -> 0 | W36: =IF(L36="",0,IF(ISNUMBER(SEARCH("Dining room",L36)),1,0)) -> 0 | X36: =IF(L36="",0,IF(ISNUMBER(SEARCH("Office",L36)),1,0)) -> 1 | Y36: =IF(L36="",0,IF(ISNUMBER(SEARCH("Bedroom",L36)),1,0)) -> 0 | Z36: =IF(L36="",0,IF(ISNUMBER(SEARCH("Living room",L36)),1,0)) -> 0 | AA36: =IF(M36="",0, IF(ISNUMBER(SEARCH("By yourself",M36)), 1, 0)) -> 1 | AB36: =IF(M36="", 0, IF(ISNUMBER(SEARCH("Friends", M36)), 1, 0)) -> 0 | AC36: =IF(M36="",0,IF(ISNUMBER(SEARCH("Family members", M36)), 1, 0)) -> 1 | AD36: =IF(M36="", 0, IF(ISNUMBER(SEARCH("Coworkers/Classmates", M36)), 1, 0)) -> 0 | AE36: =IF(M36="", 0, IF(ISNUMBER(SEARCH("Strangers", M36)), 1, 0)) -> 0 | AF36: =IF(N36="", 0, IF(ISNUMBER(SEARCH("Spring", N36)), 1, 0)) -> 0 | AG36: =IF(N36="", 0, IF(ISNUMBER(SEARCH("Summer", N36)), 1, 0)) -> 0 | AH36: =IF(N36="", 0, IF(ISNUMBER(SEARCH("Fall", N36)), 1, 0)) -> 1 | AI36: =IF(N36="", 0, IF(ISNUMBER(SEARCH("Winter", N36)), 1, 0)) -> 0
